test_absolute (__main__.TestExercice) ... ok
test_factorial (__main__.TestExercice) ... ERROR
test_prefixes (__main__.TestExercice) ... ok
test_summation (__main__.TestExercice) ... ok
test_verify_ages (__main__.TestExercice) ... ok

======================================================================
ERROR: test_factorial (__main__.TestExercice)
----------------------------------------------------------------------
Traceback (most recent call last):
  File "test_exercice.py", line 56, in test_factorial
    output = [exercice.factorial(v) for v in values]
  File "test_exercice.py", line 56, in <listcomp>
    output = [exercice.factorial(v) for v in values]
  File "/home/runner/work/2021h-ch5-exercices-phhad/2021h-ch5-exercices-phhad/exercice.py", line 47, in factorial
    return facto
UnboundLocalError: local variable 'facto' referenced before assignment

----------------------------------------------------------------------
Ran 5 tests in 0.002s

FAILED (errors=1)
